Workbook

Sheet Archive 7.8
A1: TT2 Alchemy Recipe Book
A2: - - - - - - A collection of all Alchemy Ingredients, Recipes, and Rewards - - - - - - by: rawrzcookie - - - - - -
A3: {="Recipes Remaining: " & _xludf.LAMBDA(n,matrix,offset,(n*(n+1)/2)-((n - SUM((COLUMN(matrix)-ROW(matrix)=offset)*IF(matrix<>"",1,0)))+IF(COUNTIF(matrix,"<>")>=(n^2),0,FLOOR(((n^2)-(COUNTIF(matrix,"<>")+(n - SUM((COLUMN(matrix)-ROW(matrix)=offset)*IF(matrix<>"",1,0)))))/2,1))) & "/" & (n*(n+1)/2) & " % Complete: " & ROUND(((n*(n+1)/2)-((n - SUM((COLUMN(matrix)-ROW(matrix)=offset)*IF(matrix<>"",1,0)))+IF(COUNTIF(matrix,"<>")>=(n^2),0,FLOOR(((n^2)-(COUNTIF(matrix,"<>")+(n - SUM((COLUMN(matrix)-ROW(matrix)=offset)*IF(matrix<>"",1,0)))))/2,1))))/(n*(n+1)/2),4) * 100 & "%")(16,C5:R20,(COLUMN() - ROW()))} -> #NAME? | C3: {=TRANSPOSE(A5:A20)} -> Pepper | D3: Berries | E3: Mushroom | F3: Sand | G3: Petal | H3: Acorn | I3: Feather | J3: Shadow | K3: Spirit | L3: Essence | M3: Power | N3: Beetle | O3: Tooth | P3: Flame | Q3: Steel | R3: Scale
C4: {=_xludf.XLOOKUP(C3,Images!$A:$A,Images!$C:$C,"")} -> #NAME? | D4: {=_xludf.XLOOKUP(D3,Images!$A:$A,Images!$C:$C,"")} -> #NAME? | E4: {=_xludf.XLOOKUP(E3,Images!$A:$A,Images!$C:$C,"")} -> #NAME? | F4: {=_xludf.XLOOKUP(F3,Images!$A:$A,Images!$C:$C,"")} -> #NAME? | G4: {=_xludf.XLOOKUP(G3,Images!$A:$A,Images!$C:$C,"")} -> #NAME? | H4: {=_xludf.XLOOKUP(H3,Images!$A:$A,Images!$C:$C,"")} -> #NAME? | I4: {=_xludf.XLOOKUP(I3,Images!$A:$A,Images!$C:$C,"")} -> #NAME? | J4: {=_xludf.XLOOKUP(J3,Images!$A:$A,Images!$C:$C,"")} -> #NAME? | ... R4: {=_xludf.XLOOKUP(R3,Images!$A:$A,Images!$C:$C,"")} -> #NAME?
A5: Pepper | B5: {=_xludf.XLOOKUP(A5,Images!$A:$A,Images!$C:$C,"")} -> #NAME? | C5: Event Equipment (Safety Tongs) | D5: =INDEX($C$5:$R$20, COLUMN()-2, ROW()-4) -> #NAME? | E5: =INDEX($C$5:$R$20, COLUMN()-2, ROW()-4) -> #NAME? | F5: =INDEX($C$5:$R$20, COLUMN()-2, ROW()-4) -> #NAME? | G5: =INDEX($C$5:$R$20, COLUMN()-2, ROW()-4) -> 18 Currency | H5: =INDEX($C$5:$R$20, COLUMN()-2, ROW()-4) -> 3 Eggs | I5: =INDEX($C$5:$R$20, COLUMN()-2, ROW()-4) -> 15 Common Equipment | J5: =INDEX($C$5:$R$20, COLUMN()-2, ROW()-4) -> 32 Currency | K5: =INDEX($C$5:$R$20, COLUMN()-2, ROW()-4) -> 32 Currency | ... R5: =INDEX($C$5:$R$20, COLUMN()-2, ROW()-4) -> 232 Currency
A6: Berries | B6: {=_xludf.XLOOKUP(A6,Images!$A:$A,Images!$C:$C,"")} -> #NAME? | C6: {=_xludf.XLOOKUP("Sand",Images!$A:$A,Images!$C:$C,"")} -> #NAME? | D6: 12 Currency | E6: =INDEX($C$5:$R$20, COLUMN()-2, ROW()-4) -> #NAME? | F6: =INDEX($C$5:$R$20, COLUMN()-2, ROW()-4) -> 18 Currency | G6: =INDEX($C$5:$R$20, COLUMN()-2, ROW()-4) -> 1 Perk | H6: =INDEX($C$5:$R$20, COLUMN()-2, ROW()-4) -> Event Equipment (Hair of Madness) | I6: =INDEX($C$5:$R$20, COLUMN()-2, ROW()-4) -> 2 Perks | J6: =INDEX($C$5:$R$20, COLUMN()-2, ROW()-4) -> 4 Crafting Shards | K6: =INDEX($C$5:$R$20, COLUMN()-2, ROW()-4) -> 10 Raid Cards | L6: =INDEX($C$5:$R$20, COLUMN()-2, ROW()-4) -> 60 Currency | ... R6: =INDEX($C$5:$R$20, COLUMN()-2, ROW()-4) -> 3 Clan Scrolls
A7: Mushroom | B7: {=_xludf.XLOOKUP(A7,Images!$A:$A,Images!$C:$C,"")} -> #NAME? | C7: {=_xludf.XLOOKUP("Petal",Images!$A:$A,Images!$C:$C,"")} -> #NAME? | D7: {=_xludf.XLOOKUP("Acorn",Images!$A:$A,Images!$C:$C,"")} -> #NAME? | E7: 12 Currency | F7: =INDEX($C$5:$R$20, COLUMN()-2, ROW()-4) -> 6 Raid Cards | G7: =INDEX($C$5:$R$20, COLUMN()-2, ROW()-4) -> 1 Rare Equipment | H7: =INDEX($C$5:$R$20, COLUMN()-2, ROW()-4) -> 3 Eggs | I7: =INDEX($C$5:$R$20, COLUMN()-2, ROW()-4) -> Event Equipment (Lab Coat) | J7: =INDEX($C$5:$R$20, COLUMN()-2, ROW()-4) -> 4 Crafting Shards | K7: =INDEX($C$5:$R$20, COLUMN()-2, ROW()-4) -> 10 Raid Cards | L7: =INDEX($C$5:$R$20, COLUMN()-2, ROW()-4) -> 60 Currency | M7: =INDEX($C$5:$R$20, COLUMN()-2, ROW()-4) -> 2 Skill Points | ... R7: =INDEX($C$5:$R$20, COLUMN()-2, ROW()-4) -> 232 Currency
A8: Sand | B8: {=_xludf.XLOOKUP(A8,Images!$A:$A,Images!$C:$C,"")} -> #NAME? | C8: {=_xludf.XLOOKUP("Feather",Images!$A:$A,Images!$C:$C,"")} -> #NAME? | D8: 18 Currency | E8: 6 Raid Cards | F8: 2 Rare Equipment | G8: =INDEX($C$5:$R$20, COLUMN()-2, ROW()-4) -> #NAME? | H8: =INDEX($C$5:$R$20, COLUMN()-2, ROW()-4) -> 25 Currency | I8: =INDEX($C$5:$R$20, COLUMN()-2, ROW()-4) -> 2 Hero Weapons | J8: =INDEX($C$5:$R$20, COLUMN()-2, ROW()-4) -> 12 Raid Cards | K8: =INDEX($C$5:$R$20, COLUMN()-2, ROW()-4) -> 3 Rare Equipment | L8: =INDEX($C$5:$R$20, COLUMN()-2, ROW()-4) -> 9 Crafting Shards | M8: =INDEX($C$5:$R$20, COLUMN()-2, ROW()-4) -> 16 Wildcards | N8: =INDEX($C$5:$R$20, COLUMN()-2, ROW()-4) -> 66 Currency | ... R8: =INDEX($C$5:$R$20, COLUMN()-2, ROW()-4) -> 3 Clan Scrolls
A9: Petal | B9: {=_xludf.XLOOKUP(A9,Images!$A:$A,Images!$C:$C,"")} -> #NAME? | C9: 18 Currency | D9: 1 Perk | E9: 1 Rare Equipment | F9: {=_xludf.XLOOKUP("Spirit",Images!$A:$A,Images!$C:$C,"")} -> #NAME? | G9: 25 Currency | H9: =INDEX($C$5:$R$20, COLUMN()-2, ROW()-4) -> #NAME? | I9: =INDEX($C$5:$R$20, COLUMN()-2, ROW()-4) -> Event Equipment (Molecularization) | J9: =INDEX($C$5:$R$20, COLUMN()-2, ROW()-4) -> Event Equipment (Master of Elements) | K9: =INDEX($C$5:$R$20, COLUMN()-2, ROW()-4) -> 38 Currency | L9: =INDEX($C$5:$R$20, COLUMN()-2, ROW()-4) -> 66 Currency | M9: =INDEX($C$5:$R$20, COLUMN()-2, ROW()-4) -> 2 Skill Points | N9: =INDEX($C$5:$R$20, COLUMN()-2, ROW()-4) -> 22 Raid Cards | O9: =INDEX($C$5:$R$20, COLUMN()-2, ROW()-4) -> 122 Currency | ... R9: =INDEX($C$5:$R$20, COLUMN()-2, ROW()-4) -> 238 Currency
A10: Acorn | B10: {=_xludf.XLOOKUP(A10,Images!$A:$A,Images!$C:$C,"")} -> #NAME? | C10: 3 Eggs | D10: Event Equipment (Hair of Madness) | E10: 3 Eggs | F10: 25 Currency | G10: {=_xludf.XLOOKUP("Shadow",Images!$A:$A,Images!$C:$C,"")} -> #NAME? | H10: 25 Currency | I10: =INDEX($C$5:$R$20, COLUMN()-2, ROW()-4) -> #NAME? | J10: =INDEX($C$5:$R$20, COLUMN()-2, ROW()-4) -> 12 Raid Cards | K10: =INDEX($C$5:$R$20, COLUMN()-2, ROW()-4) -> 6 Eggs | L10: =INDEX($C$5:$R$20, COLUMN()-2, ROW()-4) -> 66 Currency | M10: =INDEX($C$5:$R$20, COLUMN()-2, ROW()-4) -> 22 Raid Cards | N10: =INDEX($C$5:$R$20, COLUMN()-2, ROW()-4) -> 66 Currency | O10: =INDEX($C$5:$R$20, COLUMN()-2, ROW()-4) -> 122 Currency | P10: =INDEX($C$5:$R$20, COLUMN()-2, ROW()-4) -> 40 Raid Cards | ... R10: =INDEX($C$5:$R$20, COLUMN()-2, ROW()-4) -> 79 Raid Cards
A11: Feather | B11: {=_xludf.XLOOKUP(A11,Images!$A:$A,Images!$C:$C,"")} -> #NAME? | C11: 15 Common Equipment | D11: 2 Perks | E11: Event Equipment (Lab Coat) | F11: 2 Hero Weapons | G11: Event Equipment (Molecularization) | H11: {=_xludf.XLOOKUP("Essence",Images!$A:$A,Images!$C:$C,"")} -> #NAME? | I11: 52 Currency | J11: =INDEX($C$5:$R$20, COLUMN()-2, ROW()-4) -> #NAME? | K11: =INDEX($C$5:$R$20, COLUMN()-2, ROW()-4) -> Legendary Equipment (Granite Mail) | L11: =INDEX($C$5:$R$20, COLUMN()-2, ROW()-4) -> 80 Currency | M11: =INDEX($C$5:$R$20, COLUMN()-2, ROW()-4) -> 80 Currency | N11: =INDEX($C$5:$R$20, COLUMN()-2, ROW()-4) -> 26 Raid Cards | O11: =INDEX($C$5:$R$20, COLUMN()-2, ROW()-4) -> 136 Currency | P11: =INDEX($C$5:$R$20, COLUMN()-2, ROW()-4) -> 45 Raid Cards | Q11: =INDEX($C$5:$R$20, COLUMN()-2, ROW()-4) -> 45 Raid Cards | R11: =INDEX($C$5:$R$20, COLUMN()-2, ROW()-4) -> 252 Currency
A12: Shadow | B12: {=_xludf.XLOOKUP(A12,Images!$A:$A,Images!$C:$C,"")} -> #NAME? | C12: 32 Currency | D12: 4 Crafting Shards | E12: 4 Crafting Shards | F12: 12 Raid Cards | G12: Event Equipment (Master of Elements) | H12: 12 Raid Cards | I12: {=_xludf.XLOOKUP("Beetle",Images!$A:$A,Images!$C:$C,"")} -> #NAME? | J12: 52 Currency | K12: =INDEX($C$5:$R$20, COLUMN()-2, ROW()-4) -> #NAME? | L12: =INDEX($C$5:$R$20, COLUMN()-2, ROW()-4) -> 13 Eggs | M12: =INDEX($C$5:$R$20, COLUMN()-2, ROW()-4) -> Legendary Equipment (Stone Hammer) | N12: =INDEX($C$5:$R$20, COLUMN()-2, ROW()-4) -> 13 Eggs | O12: =INDEX($C$5:$R$20, COLUMN()-2, ROW()-4) -> 136 Currency | P12: =INDEX($C$5:$R$20, COLUMN()-2, ROW()-4) -> 22 Eggs | Q12: =INDEX($C$5:$R$20, COLUMN()-2, ROW()-4) -> 136 Currency | R12: =INDEX($C$5:$R$20, COLUMN()-2, ROW()-4) -> 3 Fortune Scrolls
A13: Spirit | B13: {=_xludf.XLOOKUP(A13,Images!$A:$A,Images!$C:$C,"")} -> #NAME? | C13: 32 Currency | D13: 10 Raid Cards | E13: 10 Raid Cards | F13: 3 Rare Equipment | G13: 38 Currency | H13: 6 Eggs | I13: Legendary Equipment (Granite Mail) | J13: {=_xludf.XLOOKUP("Power",Images!$A:$A,Images!$C:$C,"")} -> #NAME? | K13: 52 Currency | L13: =INDEX($C$5:$R$20, COLUMN()-2, ROW()-4) -> 3 Skill Points | M13: =INDEX($C$5:$R$20, COLUMN()-2, ROW()-4) -> #NAME? | N13: =INDEX($C$5:$R$20, COLUMN()-2, ROW()-4) -> 26 Raid Cards | O13: =INDEX($C$5:$R$20, COLUMN()-2, ROW()-4) -> 19 Crafting Shards | P13: =INDEX($C$5:$R$20, COLUMN()-2, ROW()-4) -> 19 Crafting Shards | Q13: =INDEX($C$5:$R$20, COLUMN()-2, ROW()-4) -> 19 Crafting Shards | R13: =INDEX($C$5:$R$20, COLUMN()-2, ROW()-4) -> 252 Currency
A14: Essence | B14: {=_xludf.XLOOKUP(A14,Images!$A:$A,Images!$C:$C,"")} -> #NAME? | C14: 20 Raid Cards | D14: 60 Currency | E14: 60 Currency | F14: 9 Crafting Shards | G14: 66 Currency | H14: 66 Currency | I14: 80 Currency | J14: 13 Eggs | K14: 3 Skill Points | L14: 108 Currency | M14: =INDEX($C$5:$R$20, COLUMN()-2, ROW()-4) -> #NAME? | N14: =INDEX($C$5:$R$20, COLUMN()-2, ROW()-4) -> Avatar + 108 Currency | O14: =INDEX($C$5:$R$20, COLUMN()-2, ROW()-4) -> 8 Fortune Weapons | P14: =INDEX($C$5:$R$20, COLUMN()-2, ROW()-4) -> 54 Raid Cards | Q14: =INDEX($C$5:$R$20, COLUMN()-2, ROW()-4) -> 54 Raid Cards | R14: =INDEX($C$5:$R$20, COLUMN()-2, ROW()-4) -> 3 Fortune Scrolls
A15: Power | B15: {=_xludf.XLOOKUP(A15,Images!$A:$A,Images!$C:$C,"")} -> #NAME? | C15: 2 Skill Points | D15: 20 Currency | E15: 2 Skill Points | F15: 16 Wildcards | G15: 2 Skill Points | H15: 22 Raid Cards | I15: 80 Currency | J15: Legendary Equipment (Stone Hammer) | K15: {=_xludf.XLOOKUP("Steel",Images!$A:$A,Images!$C:$C,"")} -> #NAME? | L15: {=_xludf.XLOOKUP("Tooth",Images!$A:$A,Images!$C:$C,"")} -> #NAME? | M15: Legendary Equipment (Gravel Explosion) | N15: =INDEX($C$5:$R$20, COLUMN()-2, ROW()-4) -> #NAME? | O15: =INDEX($C$5:$R$20, COLUMN()-2, ROW()-4) -> 164 Currency | P15: =INDEX($C$5:$R$20, COLUMN()-2, ROW()-4) -> 164 Currency | Q15: =INDEX($C$5:$R$20, COLUMN()-2, ROW()-4) -> 41 Wildcards | R15: =INDEX($C$5:$R$20, COLUMN()-2, ROW()-4) -> 280 Currency
A16: Beetle | B16: {=_xludf.XLOOKUP(A16,Images!$A:$A,Images!$C:$C,"")} -> #NAME? | C16: 4 Hero Weapons | D16: 3 Perks | E16: 60 Currency | F16: 66 Currency | G16: 22 Raid Cards | H16: 66 Currency | I16: 26 Raid Cards | J16: 13 Eggs | K16: 26 Raid Cards | L16: Avatar + 108 Currency | M16: {=_xludf.XLOOKUP("Flame",Images!$A:$A,Images!$C:$C,"")} -> #NAME? | N16: 4 Skill Points | O16: =INDEX($C$5:$R$20, COLUMN()-2, ROW()-4) -> 8 Fortune Weapons | P16: =INDEX($C$5:$R$20, COLUMN()-2, ROW()-4) -> 2 Fortune Scrolls | Q16: =INDEX($C$5:$R$20, COLUMN()-2, ROW()-4) -> 6 Skill Points | R16: =INDEX($C$5:$R$20, COLUMN()-2, ROW()-4) -> 11 Skill Points
A17: Tooth | B17: {=_xludf.XLOOKUP(A17,Images!$A:$A,Images!$C:$C,"")} -> #NAME? | C17: 116 Currency | D17: 116 Currency | E17: 116 Currency | F17: 122 Currency | G17: 122 Currency | H17: 122 Currency | I17: 136 Currency | J17: 136 Currency | K17: 19 Crafting Shards | L17: 8 Fortune Weapons | M17: 164 Currency | N17: 8 Fortune Weapons | O17: 220 Currency | P17: =INDEX($C$5:$R$20, COLUMN()-2, ROW()-4) -> 11 Fortune Weapons | Q17: =INDEX($C$5:$R$20, COLUMN()-2, ROW()-4) -> #NAME? | R17: =INDEX($C$5:$R$20, COLUMN()-2, ROW()-4) -> 84 Wildcards
A18: Flame | B18: {=_xludf.XLOOKUP(A18,Images!$A:$A,Images!$C:$C,"")} -> #NAME? | C18: 1 Clan Scroll | D18: 116 Currency | E18: 116 Currency | F18: 122 Currency | G18: 122 Currency | H18: 40 Raid Cards | I18: 45 Raid Cards | J18: 22 Eggs | K18: 19 Crafting Shards | L18: 54 Raid Cards | M18: 164 Currency | N18: 2 Fortune Scrolls | O18: 11 Fortune Weapons | P18: 220 Currency | Q18: =INDEX($C$5:$R$20, COLUMN()-2, ROW()-4) -> 220 Currency | R18: =INDEX($C$5:$R$20, COLUMN()-2, ROW()-4) -> 84 Wildcards
A19: Steel | B19: {=_xludf.XLOOKUP(A19,Images!$A:$A,Images!$C:$C,"")} -> #NAME? | C19: 116 Currency | D19: 116 Currency | E19: 116 Currency | F19: 12 Rare Equipment | G19: 8 Hero Weapons | H19: 122 Currency | I19: 45 Raid Cards | J19: 136 Currency | K19: 19 Crafting Shards | L19: 54 Raid Cards | M19: 41 Wildcards | N19: 6 Skill Points | O19: {=_xludf.XLOOKUP("Scale",Images!$A:$A,Images!$C:$C,"")} -> #NAME? | P19: 220 Currency | Q19: 2 Fortune Scrolls | R19: {=INDEX($C$5:$R$20, COLUMN()-2, ROW()-4)} -> 336 Currency
A20: Scale | B20: {=_xludf.XLOOKUP(A20,Images!$A:$A,Images!$C:$C,"")} -> #NAME? | C20: 232 Currency | D20: 3 Clan Scrolls | E20: 232 Currency | F20: 3 Clan Scrolls | G20: 238 Currency | H20: 79 Raid Cards | I20: 252 Currency | J20: 3 Fortune Scrolls | K20: 252 Currency | L20: 3 Fortune Scrolls | M20: 280 Currency | N20: 11 Skill Points | O20: 84 Wildcards | P20: 84 Wildcards | Q20: 336 Currency | R20: 1 Legendary Equipment

Sheet Recipe Matrix
A1: TT2 Alchemy Recipe Book
A2: - - - - - - A collection of all Alchemy Ingredients, Recipes, and Rewards - - - - - - by: rawrzcookie - - - - - -
B3: {=TRANSPOSE(A4:A19)} -> Poison | C3: Tooth | D3: Steel | E3: Power | F3: Spirit | G3: Feather | H3: Egg | I3: Mushroom | J3: Pepper | K3: Sand | L3: Lightning | M3: Beetle | N3: Flame | O3: Scale | P3: Essence | Q3: Shadow
A4: Poison | B4: 1 Pet Egg | C4: Power | D4: Spirit | E4: Event Equipment | F4: 18 Currency | G4: Egg | H4: 1 Skill Point | I4: 32 Currency | J4: 32 Currency | K4: 20 Raid Cards | L4: 2 Skill Points | M4: 4 Hero Weapons | N4: 116 Currency | O4: 1 Clan Scroll | P4: 116 Currency | Q4: 222 Currency
A5: Tooth | B5: Power | C5: 12 Currency | D5: Feather | E5: 18 Currency | F5: 1 Perk | G5: Event Equipment | H5: 10 Raid Cards | I5: 4 Crafting Shards | J5: 2 Perks | K5: 60 Currency | L5: 20 Raid Cards | M5: 3 Perks | N5: 116 Currency | O5: 116 Currency | P5: 116 Currency | Q5: 3 Clan Scrolls
A6: Steel | B6: Spirit | C6: Feather | D6: 12 Currency | E6: 6 Raid Cards | F6: 1 Rare Equipment | G6: 3 Pet Eggs | H6: 10 Raid Cards | I6: 4 Crafting Shards | J6: Event Equipment (Lab Coat) | K6: 60 Currency | L6: 2 Skill Points | M6: 60 Currency | N6: 116 currency | O6: 116 Currency | P6: 116 Currency | Q6: 232 Currency
A7: Power | B7: Event Equipment | C7: 18 Currency | D7: 6 Raid Cards | E7: 2 Rare Equipment | F7: 25 Currency | G7: Pepper | H7: 2 Hero Weapons | I7: 12 Raid Cards | J7: 3 Rare Equipment | K7: 9 Crafting Shards | L7: 16 Wildcards | M7: 66 Currency | N7: 122 Currency | O7: 122 Currency | P7: 12 Rare Equipment | Q7: 3 Clan Scrolls
A8: Spirit | B8: 18 Currency | C8: 1 Perk | D8: 1 Rare Equipment | E8: 25 Currency | F8: 25 Currency | G8: Mushroom | H8: 38 Currency | I8: 38 Currency | J8: Event Equipment | K8: 66 Currency | L8: 2 Skill Points | M8: 22 Raid Cards | N8: 122 Currency | O8: Event Equipment | P8: 8 Hero Weapons | Q8: 238 Currency
A9: Feather | B9: Egg | C9: Event Equipment | D9: 3 Pet Eggs | E9: Pepper | F9: Mushroom | G9: 25 Currency | H9: 6 Pet Eggs | I9: 12 Raid Cards | J9: Sand | K9: 66 Currency | L9: 22 Raid cards | M9: 66 Currency | N9: 122 Currency | O9: 122 Currency | P9: 40 Raid Cards | Q9: 39 Pet Eggs
A10: Egg | B10: 1 Skill Point | C10: 10 Raid Cards | D10: 10 Raid Cards | E10: 2 Hero Weapons | F10: 38 Currency | G10: 6 Pet Eggs | H10: 52 Currency | I10: Legendary Equip (Shadowgold Armor) | J10: Beetle | K10: 13 Pet Eggs | L10: 80 Currency | M10: 26 Raid Cards | N10: 136 Currency | O10: 136 Currency | P10: 45 Raid Cards | Q10: 252 Currency
A11: Mushroom | B11: 32 Currency | C11: 4 Crafting Shards | D11: 4 Crafting Shards | E11: 12 Raid Cards | F11: 38 Currency | G11: 12 Raid Cards | H11: Legendary Equip (Shadowgold Armor) | I11: 52 Currency | J11: Lightning | K11: 13 Pet Eggs | L11: Legendary Equipment (Shadowgold Goblet) | M11: 13 Pet Eggs | N11: 136 Currency | O11: 22 Pet Eggs | P11: 19 Crafting Shards | Q11: 3 Fortune Scrolls
A12: Pepper | B12: 32 Currency | C12: 2 Perks | D12: Event Equipment (Lab Coat) | E12: 3 Rare Equipment | F12: Event Equipment (Master of Elements) | G12: Sand | H12: Beetle | I12: Lightning | J12: 52 Currency | K12: 3 Skill Points | L12: Essence | M12: 11 Crafting Shards | N12: 19 Crafting Shards | O12: 19 Crafting Shards | P12: 19 Crafting Shards | Q12: 252 Currency
A13: Sand | B13: 20 Raid Cards | C13: 60 Currency | D13: 60 Currency | E13: 9 Crafting Shards | F13: 66 Currency | G13: 66 Currency | H13: 13 Pet Eggs | I13: 13 Pet Eggs | J13: 3 Skill Points | K13: 108 Currency | L13: 108 Currency | M13: Flame | N13: 8 Fortune Weapons | O13: 54 Raid Cards | P13: 54 Raid Cards | Q13: 3 Fortune Scrolls
A14: Lightning | B14: 2 Skill Points | C14: 20 Raid Cards | D14: 2 Skill Points | E14: 16 Wildcards | F14: 2 Skill Points | G14: 22 Raid cards | H14: 80 Currency | I14: Legendary Equipment | J14: Essence | K14: 108 Currency | L14: Legendary Equipment (Shackles of Greed) | M14: Scale | N14: 164 Currency | O14: 164 Currency | P14: 41 Wildcards | Q14: 280 Currency
A15: Beetle | B15: 4 Hero Weapons | C15: 3 Perks | D15: 60 Currency | E15: 66 Currency | F15: 22 Raid Cards | G15: 66 Currency | H15: 26 Raid Cards | I15: 13 Pet Eggs | J15: 11 Crafting Shards | K15: Flame | L15: Scale | M15: 4 Skill Points | N15: Legendary Equipment | O15: Legendary Equipment | P15: 6 Skill Point | Q15: 11 Skill Points
... A19: Shadow | B19: 222 Currency | C19: 3 Clan Scrolls | D19: 232 Currency | E19: 3 Clan Scrolls | F19: 238 Currency | G19: 39 Pet Eggs | H19: 252 Currency | I19: 3 Fortune Scrolls | J19: 252 Currency | K19: 3 Fortune Scrolls | L19: 280 Currency | M19: 11 Skill Points | N19: 84 Wildcards | O19: 84 Wildcards | P19: 336 Currency | Q19: 1 Legendary Insult

Sheet Calculations
AB1: chec
B2: Poison | C2: Tooth | D2: Steel | E2: Power | F2: Spirit | G2: Feather | H2: Egg | I2: Mushroom | J2: Pepper | K2: Sand | L2: Lightning | M2: Beetle | N2: Flame | O2: Scale | P2: Essence | Q2: Shadow | X2: Old | Y2: New | AH2: Old
A3: Poison | B3: ='Recipe Matrix'!B4 -> 1 Pet Egg | C3: ='Recipe Matrix'!C4 -> Power | D3: ='Recipe Matrix'!D4 -> Spirit | E3: ='Recipe Matrix'!E4 -> Event Equipment | F3: ='Recipe Matrix'!F4 -> 18 Currency | G3: ='Recipe Matrix'!G4 -> Egg | H3: ='Recipe Matrix'!H4 -> 1 Skill Point | I3: ='Recipe Matrix'!I4 -> 32 Currency | ... Q3: ='Recipe Matrix'!Q4 -> 222 Currency | S3: {=_xlfn.UNIQUE(_xlfn.TOCOL(B3:Q18))} -> 1 Pet Egg | U3: =IF(ISNUMBER(1*LEFT(S3, 1)), RIGHT(S3,LEN(S3)-SEARCH(" ",S3)),S3) -> Pet Egg | V3: =ISNUMBER(MATCH(U3,$A$3:$A$18,0)) -> FALSE | X3: {=_xlfn._xlws.SORT(_xlfn.UNIQUE(_xlfn._xlws.FILTER(U3:U127,V3:V127=FALSE)),1,-1)} -> Wildcards | Y3: =X3 -> Wildcards | AC3: {=_xlfn.UNIQUE(_xlfn.TOCOL(B22:Q37))} -> 1 Pet Eggs | AE3: =IF(ISNUMBER(1*LEFT(AC3, 1)), RIGHT(AC3,LEN(AC3)-SEARCH(" ",AC3)),AC3) -> Pet Eggs | AF3: =ISNUMBER(MATCH(AE3,$A$3:$A$18,0)) -> FALSE | AH3: {=_xlfn._xlws.SORT(_xlfn.UNIQUE(_xlfn._xlws.FILTER(AE3:AE127,AF3:AF127=FALSE)))} -> 0
A4: Tooth | B4: ='Recipe Matrix'!B5 -> Power | C4: ='Recipe Matrix'!C5 -> 12 Currency | D4: ='Recipe Matrix'!D5 -> Feather | E4: ='Recipe Matrix'!E5 -> 18 Currency | F4: ='Recipe Matrix'!F5 -> 1 Perk | G4: ='Recipe Matrix'!G5 -> Event Equipment | H4: ='Recipe Matrix'!H5 -> 10 Raid Cards | I4: ='Recipe Matrix'!I5 -> 4 Crafting Shards | ... Q4: ='Recipe Matrix'!Q5 -> 3 Clan Scrolls | S4: Power | U4: =IF(ISNUMBER(1*LEFT(S4, 1)), RIGHT(S4,LEN(S4)-SEARCH(" ",S4)),S4) -> Power | V4: =ISNUMBER(MATCH(U4,$A$3:$A$18,0)) -> TRUE | X4: Skill Points | Y4: Skill Point | AC4: Power | AE4: =IF(ISNUMBER(1*LEFT(AC4, 1)), RIGHT(AC4,LEN(AC4)-SEARCH(" ",AC4)),AC4) -> Power | AF4: =ISNUMBER(MATCH(AE4,$A$3:$A$18,0)) -> TRUE | AH4: Clan Scrolls
A5: Steel | B5: ='Recipe Matrix'!B6 -> Spirit | C5: ='Recipe Matrix'!C6 -> Feather | D5: ='Recipe Matrix'!D6 -> 12 Currency | E5: ='Recipe Matrix'!E6 -> 6 Raid Cards | F5: ='Recipe Matrix'!F6 -> 1 Rare Equipment | G5: ='Recipe Matrix'!G6 -> 3 Pet Eggs | H5: ='Recipe Matrix'!H6 -> 10 Raid Cards | I5: ='Recipe Matrix'!I6 -> 4 Crafting Shards | ... Q5: ='Recipe Matrix'!Q6 -> 232 Currency | S5: Spirit | U5: =IF(ISNUMBER(1*LEFT(S5, 1)), RIGHT(S5,LEN(S5)-SEARCH(" ",S5)),S5) -> Spirit | V5: =ISNUMBER(MATCH(U5,$A$3:$A$18,0)) -> TRUE | X5: Skill Point | Y5: Skill Points | AC5: Spirit | AE5: =IF(ISNUMBER(1*LEFT(AC5, 1)), RIGHT(AC5,LEN(AC5)-SEARCH(" ",AC5)),AC5) -> Spirit | AF5: =ISNUMBER(MATCH(AE5,$A$3:$A$18,0)) -> TRUE | AH5: Crafting Shards
A6: Power | B6: ='Recipe Matrix'!B7 -> Event Equipment | C6: ='Recipe Matrix'!C7 -> 18 Currency | D6: ='Recipe Matrix'!D7 -> 6 Raid Cards | E6: ='Recipe Matrix'!E7 -> 2 Rare Equipment | F6: ='Recipe Matrix'!F7 -> 25 Currency | G6: ='Recipe Matrix'!G7 -> Pepper | H6: ='Recipe Matrix'!H7 -> 2 Hero Weapons | I6: ='Recipe Matrix'!I7 -> 12 Raid Cards | ... Q6: ='Recipe Matrix'!Q7 -> 3 Clan Scrolls | S6: Event Equipment | U6: =IF(ISNUMBER(1*LEFT(S6, 1)), RIGHT(S6,LEN(S6)-SEARCH(" ",S6)),S6) -> Event Equipment | V6: =ISNUMBER(MATCH(U6,$A$3:$A$18,0)) -> FALSE | X6: Rare Equipment | Y6: Event Equipment | AC6: Event Equipment | AE6: =IF(ISNUMBER(1*LEFT(AC6, 1)), RIGHT(AC6,LEN(AC6)-SEARCH(" ",AC6)),AC6) -> Event Equipment | AF6: =ISNUMBER(MATCH(AE6,$A$3:$A$18,0)) -> FALSE | AH6: Currency
A7: Spirit | B7: ='Recipe Matrix'!B8 -> 18 Currency | C7: ='Recipe Matrix'!C8 -> 1 Perk | D7: ='Recipe Matrix'!D8 -> 1 Rare Equipment | E7: ='Recipe Matrix'!E8 -> 25 Currency | F7: ='Recipe Matrix'!F8 -> 25 Currency | G7: ='Recipe Matrix'!G8 -> Mushroom | H7: ='Recipe Matrix'!H8 -> 38 Currency | I7: ='Recipe Matrix'!I8 -> 38 Currency | ... Q7: ='Recipe Matrix'!Q8 -> 238 Currency | S7: 18 Currency | U7: =IF(ISNUMBER(1*LEFT(S7, 1)), RIGHT(S7,LEN(S7)-SEARCH(" ",S7)),S7) -> Currency | V7: =ISNUMBER(MATCH(U7,$A$3:$A$18,0)) -> FALSE | X7: Raid Cards | Y7: Raid Cards | AC7: 18 Currency | AE7: =IF(ISNUMBER(1*LEFT(AC7, 1)), RIGHT(AC7,LEN(AC7)-SEARCH(" ",AC7)),AC7) -> Currency | AF7: =ISNUMBER(MATCH(AE7,$A$3:$A$18,0)) -> FALSE | AH7: Event Equipment
A8: Feather | B8: ='Recipe Matrix'!B9 -> Egg | C8: ='Recipe Matrix'!C9 -> Event Equipment | D8: ='Recipe Matrix'!D9 -> 3 Pet Eggs | E8: ='Recipe Matrix'!E9 -> Pepper | F8: ='Recipe Matrix'!F9 -> Mushroom | G8: ='Recipe Matrix'!G9 -> 25 Currency | H8: ='Recipe Matrix'!H9 -> 6 Pet Eggs | I8: ='Recipe Matrix'!I9 -> 12 Raid Cards | ... Q8: ='Recipe Matrix'!Q9 -> 39 Pet Eggs | S8: Egg | U8: =IF(ISNUMBER(1*LEFT(S8, 1)), RIGHT(S8,LEN(S8)-SEARCH(" ",S8)),S8) -> Egg | V8: =ISNUMBER(MATCH(U8,$A$3:$A$18,0)) -> TRUE | X8: Pet Eggs | Y8: Pet Egg | AC8: Egg | AE8: =IF(ISNUMBER(1*LEFT(AC8, 1)), RIGHT(AC8,LEN(AC8)-SEARCH(" ",AC8)),AC8) -> Egg | AF8: =ISNUMBER(MATCH(AE8,$A$3:$A$18,0)) -> TRUE | AH8: Fortune Scrolls
A9: Egg | B9: ='Recipe Matrix'!B10 -> 1 Skill Point | C9: ='Recipe Matrix'!C10 -> 10 Raid Cards | D9: ='Recipe Matrix'!D10 -> 10 Raid Cards | E9: ='Recipe Matrix'!E10 -> 2 Hero Weapons | F9: ='Recipe Matrix'!F10 -> 38 Currency | G9: ='Recipe Matrix'!G10 -> 6 Pet Eggs | H9: ='Recipe Matrix'!H10 -> 52 Currency | I9: ='Recipe Matrix'!I10 -> Legendary Equip (Shadowgold Armor) | ... Q9: ='Recipe Matrix'!Q10 -> 252 Currency | S9: 1 Skill Point | U9: =IF(ISNUMBER(1*LEFT(S9, 1)), RIGHT(S9,LEN(S9)-SEARCH(" ",S9)),S9) -> Skill Point | V9: =ISNUMBER(MATCH(U9,$A$3:$A$18,0)) -> FALSE | X9: Pet Egg | Y9: Pet Eggs | AC9: 1 Skill Points | AE9: =IF(ISNUMBER(1*LEFT(AC9, 1)), RIGHT(AC9,LEN(AC9)-SEARCH(" ",AC9)),AC9) -> Skill Points | AF9: =ISNUMBER(MATCH(AE9,$A$3:$A$18,0)) -> FALSE | AH9: Fortune Weapons
A10: Mushroom | B10: ='Recipe Matrix'!B11 -> 32 Currency | C10: ='Recipe Matrix'!C11 -> 4 Crafting Shards | D10: ='Recipe Matrix'!D11 -> 4 Crafting Shards | E10: ='Recipe Matrix'!E11 -> 12 Raid Cards | F10: ='Recipe Matrix'!F11 -> 38 Currency | G10: ='Recipe Matrix'!G11 -> 12 Raid Cards | H10: ='Recipe Matrix'!H11 -> Legendary Equip (Shadowgold Armor) | I10: ='Recipe Matrix'!I11 -> 52 Currency | ... Q10: ='Recipe Matrix'!Q11 -> 3 Fortune Scrolls | S10: 32 Currency | U10: =IF(ISNUMBER(1*LEFT(S10, 1)), RIGHT(S10,LEN(S10)-SEARCH(" ",S10)),S10) -> Currency | V10: =ISNUMBER(MATCH(U10,$A$3:$A$18,0)) -> FALSE | X10: Perks | Y10: Perk | AC10: 32 Currency | AE10: =IF(ISNUMBER(1*LEFT(AC10, 1)), RIGHT(AC10,LEN(AC10)-SEARCH(" ",AC10)),AC10) -> Currency | AF10: =ISNUMBER(MATCH(AE10,$A$3:$A$18,0)) -> FALSE | AH10: Hero Weapons
A11: Pepper | B11: ='Recipe Matrix'!B12 -> 32 Currency | C11: ='Recipe Matrix'!C12 -> 2 Perks | D11: ='Recipe Matrix'!D12 -> Event Equipment (Lab Coat) | E11: ='Recipe Matrix'!E12 -> 3 Rare Equipment | F11: ='Recipe Matrix'!F12 -> Event Equipment (Master of Elements) | G11: ='Recipe Matrix'!G12 -> Sand | H11: ='Recipe Matrix'!H12 -> Beetle | I11: ='Recipe Matrix'!I12 -> Lightning | ... Q11: ='Recipe Matrix'!Q12 -> 252 Currency | S11: 20 Raid Cards | U11: =IF(ISNUMBER(1*LEFT(S11, 1)), RIGHT(S11,LEN(S11)-SEARCH(" ",S11)),S11) -> Raid Cards | V11: =ISNUMBER(MATCH(U11,$A$3:$A$18,0)) -> FALSE | X11: Perk | Y11: Perks | AC11: 2 Raid Cards | AE11: =IF(ISNUMBER(1*LEFT(AC11, 1)), RIGHT(AC11,LEN(AC11)-SEARCH(" ",AC11)),AC11) -> Raid Cards | AF11: =ISNUMBER(MATCH(AE11,$A$3:$A$18,0)) -> FALSE | AH11: Legendary Equipment
A12: Sand | B12: ='Recipe Matrix'!B13 -> 20 Raid Cards | C12: ='Recipe Matrix'!C13 -> 60 Currency | D12: ='Recipe Matrix'!D13 -> 60 Currency | E12: ='Recipe Matrix'!E13 -> 9 Crafting Shards | F12: ='Recipe Matrix'!F13 -> 66 Currency | G12: ='Recipe Matrix'!G13 -> 66 Currency | H12: ='Recipe Matrix'!H13 -> 13 Pet Eggs | I12: ='Recipe Matrix'!I13 -> 13 Pet Eggs | ... Q12: ='Recipe Matrix'!Q13 -> 3 Fortune Scrolls | S12: 2 Skill Points | U12: =IF(ISNUMBER(1*LEFT(S12, 1)), RIGHT(S12,LEN(S12)-SEARCH(" ",S12)),S12) -> Skill Points | V12: =ISNUMBER(MATCH(U12,$A$3:$A$18,0)) -> FALSE | X12: Legendary Insult | Y12: Legendary Equipment | AC12: 2 Skill Points | AE12: =IF(ISNUMBER(1*LEFT(AC12, 1)), RIGHT(AC12,LEN(AC12)-SEARCH(" ",AC12)),AC12) -> Skill Points | AF12: =ISNUMBER(MATCH(AE12,$A$3:$A$18,0)) -> FALSE | AH12: Perks
A13: Lightning | B13: ='Recipe Matrix'!B14 -> 2 Skill Points | C13: ='Recipe Matrix'!C14 -> 20 Raid Cards | D13: ='Recipe Matrix'!D14 -> 2 Skill Points | E13: ='Recipe Matrix'!E14 -> 16 Wildcards | F13: ='Recipe Matrix'!F14 -> 2 Skill Points | G13: ='Recipe Matrix'!G14 -> 22 Raid cards | H13: ='Recipe Matrix'!H14 -> 80 Currency | I13: ='Recipe Matrix'!I14 -> Legendary Equipment | ... Q13: ='Recipe Matrix'!Q14 -> 280 Currency | S13: 4 Hero Weapons | U13: =IF(ISNUMBER(1*LEFT(S13, 1)), RIGHT(S13,LEN(S13)-SEARCH(" ",S13)),S13) -> Hero Weapons | V13: =ISNUMBER(MATCH(U13,$A$3:$A$18,0)) -> FALSE | X13: Legendary Equipment (Shadowgold Goblet) | Y13: Legendary Equipment | AC13: 4 Hero Weapons | AE13: =IF(ISNUMBER(1*LEFT(AC13, 1)), RIGHT(AC13,LEN(AC13)-SEARCH(" ",AC13)),AC13) -> Hero Weapons | AF13: =ISNUMBER(MATCH(AE13,$A$3:$A$18,0)) -> FALSE | AH13: Pet Eggs
A14: Beetle | B14: ='Recipe Matrix'!B15 -> 4 Hero Weapons | C14: ='Recipe Matrix'!C15 -> 3 Perks | D14: ='Recipe Matrix'!D15 -> 60 Currency | E14: ='Recipe Matrix'!E15 -> 66 Currency | F14: ='Recipe Matrix'!F15 -> 22 Raid Cards | G14: ='Recipe Matrix'!G15 -> 66 Currency | H14: ='Recipe Matrix'!H15 -> 26 Raid Cards | I14: ='Recipe Matrix'!I15 -> 13 Pet Eggs | ... Q14: ='Recipe Matrix'!Q15 -> 11 Skill Points | S14: 116 Currency | U14: =IF(ISNUMBER(1*LEFT(S14, 1)), RIGHT(S14,LEN(S14)-SEARCH(" ",S14)),S14) -> Currency | V14: =ISNUMBER(MATCH(U14,$A$3:$A$18,0)) -> FALSE | X14: Legendary Equipment (Shackles of Greed) | Y14: Legendary Equipment | AC14: 116 Currency | AE14: =IF(ISNUMBER(1*LEFT(AC14, 1)), RIGHT(AC14,LEN(AC14)-SEARCH(" ",AC14)),AC14) -> Currency | AF14: =ISNUMBER(MATCH(AE14,$A$3:$A$18,0)) -> FALSE | AH14: Raid Cards
A15: Flame | B15: ='Recipe Matrix'!B16 -> 116 Currency | C15: ='Recipe Matrix'!C16 -> 116 Currency | D15: ='Recipe Matrix'!D16 -> 116 currency | E15: ='Recipe Matrix'!E16 -> 122 Currency | F15: ='Recipe Matrix'!F16 -> 122 Currency | G15: ='Recipe Matrix'!G16 -> 122 Currency | H15: ='Recipe Matrix'!H16 -> 136 Currency | I15: ='Recipe Matrix'!I16 -> 136 Currency | ... Q15: ='Recipe Matrix'!Q16 -> 84 Wildcards | S15: 1 Clan Scroll | U15: =IF(ISNUMBER(1*LEFT(S15, 1)), RIGHT(S15,LEN(S15)-SEARCH(" ",S15)),S15) -> Clan Scroll | V15: =ISNUMBER(MATCH(U15,$A$3:$A$18,0)) -> FALSE | X15: Legendary Equipment | Y15: Legendary Equipment | AC15: 1 Clan Scrolls | AE15: =IF(ISNUMBER(1*LEFT(AC15, 1)), RIGHT(AC15,LEN(AC15)-SEARCH(" ",AC15)),AC15) -> Clan Scrolls | AF15: =ISNUMBER(MATCH(AE15,$A$3:$A$18,0)) -> FALSE | AH15: Skill Points
A16: Scale | B16: ='Recipe Matrix'!B17 -> 1 Clan Scroll | C16: ='Recipe Matrix'!C17 -> 116 Currency | D16: ='Recipe Matrix'!D17 -> 116 Currency | E16: ='Recipe Matrix'!E17 -> 122 Currency | F16: ='Recipe Matrix'!F17 -> Event Equipment | G16: ='Recipe Matrix'!G17 -> 122 Currency | H16: ='Recipe Matrix'!H17 -> 136 Currency | I16: ='Recipe Matrix'!I17 -> 22 Pet Eggs | ... Q16: ='Recipe Matrix'!Q17 -> 84 Wildcards | S16: 222 Currency | U16: =IF(ISNUMBER(1*LEFT(S16, 1)), RIGHT(S16,LEN(S16)-SEARCH(" ",S16)),S16) -> Currency | V16: =ISNUMBER(MATCH(U16,$A$3:$A$18,0)) -> FALSE | X16: Legendary Equip (Shadowgold Armor) | Y16: Legendary Equipment | AC16: 222 Currency | AE16: =IF(ISNUMBER(1*LEFT(AC16, 1)), RIGHT(AC16,LEN(AC16)-SEARCH(" ",AC16)),AC16) -> Currency | AF16: =ISNUMBER(MATCH(AE16,$A$3:$A$18,0)) -> FALSE | AH16: Wildcards
A17: Essence | B17: ='Recipe Matrix'!B18 -> 116 Currency | C17: ='Recipe Matrix'!C18 -> 116 Currency | D17: ='Recipe Matrix'!D18 -> 116 Currency | E17: ='Recipe Matrix'!E18 -> 12 Rare Equipment | F17: ='Recipe Matrix'!F18 -> 8 Hero Weapons | G17: ='Recipe Matrix'!G18 -> 40 Raid Cards | H17: ='Recipe Matrix'!H18 -> 45 Raid Cards | I17: ='Recipe Matrix'!I18 -> 19 Crafting Shards | ... Q17: ='Recipe Matrix'!Q18 -> 336 Currency | S17: 12 Currency | U17: =IF(ISNUMBER(1*LEFT(S17, 1)), RIGHT(S17,LEN(S17)-SEARCH(" ",S17)),S17) -> Currency | V17: =ISNUMBER(MATCH(U17,$A$3:$A$18,0)) -> FALSE | X17: Hero Weapons | Y17: Hero Weapons | AC17: 12 Currency | AE17: =IF(ISNUMBER(1*LEFT(AC17, 1)), RIGHT(AC17,LEN(AC17)-SEARCH(" ",AC17)),AC17) -> Currency | AF17: =ISNUMBER(MATCH(AE17,$A$3:$A$18,0)) -> FALSE
A18: Shadow | B18: ='Recipe Matrix'!B19 -> 222 Currency | C18: ='Recipe Matrix'!C19 -> 3 Clan Scrolls | D18: ='Recipe Matrix'!D19 -> 232 Currency | E18: ='Recipe Matrix'!E19 -> 3 Clan Scrolls | F18: ='Recipe Matrix'!F19 -> 238 Currency | G18: ='Recipe Matrix'!G19 -> 39 Pet Eggs | H18: ='Recipe Matrix'!H19 -> 252 Currency | I18: ='Recipe Matrix'!I19 -> 3 Fortune Scrolls | ... Q18: ='Recipe Matrix'!Q19 -> 1 Legendary Insult | S18: Feather | U18: =IF(ISNUMBER(1*LEFT(S18, 1)), RIGHT(S18,LEN(S18)-SEARCH(" ",S18)),S18) -> Feather | V18: =ISNUMBER(MATCH(U18,$A$3:$A$18,0)) -> TRUE | X18: Fortune Weapons | Y18: Fortune Weapons | AC18: Feather | AE18: =IF(ISNUMBER(1*LEFT(AC18, 1)), RIGHT(AC18,LEN(AC18)-SEARCH(" ",AC18)),AC18) -> Feather | AF18: =ISNUMBER(MATCH(AE18,$A$3:$A$18,0)) -> TRUE
S19: 1 Perk | U19: =IF(ISNUMBER(1*LEFT(S19, 1)), RIGHT(S19,LEN(S19)-SEARCH(" ",S19)),S19) -> Perk | V19: =ISNUMBER(MATCH(U19,$A$3:$A$18,0)) -> FALSE | X19: Fortune Scrolls | Y19: Fortune Scrolls | AC19: 1 Perks | AE19: =IF(ISNUMBER(1*LEFT(AC19, 1)), RIGHT(AC19,LEN(AC19)-SEARCH(" ",AC19)),AC19) -> Perks | AF19: =ISNUMBER(MATCH(AE19,$A$3:$A$18,0)) -> FALSE
A20: Substituted | S20: 10 Raid Cards | U20: =IF(ISNUMBER(1*LEFT(S20, 1)), RIGHT(S20,LEN(S20)-SEARCH(" ",S20)),S20) -> Raid Cards | V20: =ISNUMBER(MATCH(U20,$A$3:$A$18,0)) -> FALSE | X20: Event Equipment (Master of Elements) | Y20: Event Equipment | AC20: 1 Raid Cards | AE20: =IF(ISNUMBER(1*LEFT(AC20, 1)), RIGHT(AC20,LEN(AC20)-SEARCH(" ",AC20)),AC20) -> Raid Cards | AF20: =ISNUMBER(MATCH(AE20,$A$3:$A$18,0)) -> FALSE
A21: {=_xlfn.LET( _xlpm.txt, A2, _xlpm.findRange, $X$3:$X$30, _xlpm.replRange, $Y$3:$Y$30, _xlpm.n, ROWS(_xlpm.findRange), _xlfn.REDUCE( _xlpm.txt, _xlfn.SEQUENCE(_xlpm.n), _xlfn.LAMBDA(_xlpm.acc,_xlpm.i, SUBSTITUTE( _xlpm.acc, INDEX(_xlpm.findRange, _xlpm.i), INDEX(_xlpm.replRange, _xlpm.i) ) ) ) )} | B21: {=_xlfn.LET( _xlpm.txt, B2, _xlpm.findRange, $X$3:$X$30, _xlpm.replRange, $Y$3:$Y$30, _xlpm.n, ROWS(_xlpm.findRange), _xlfn.REDUCE( _xlpm.txt, _xlfn.SEQUENCE(_xlpm.n), _xlfn.LAMBDA(_xlpm.acc,_xlpm.i, SUBSTITUTE( _xlpm.acc, INDEX(_xlpm.findRange, _xlpm.i), INDEX(_xlpm.replRange, _xlpm.i) ) ) ) )} -> Poison | C21: {=_xlfn.LET( _xlpm.txt, C2, _xlpm.findRange, $X$3:$X$30, _xlpm.replRange, $Y$3:$Y$30, _xlpm.n, ROWS(_xlpm.findRange), _xlfn.REDUCE( _xlpm.txt, _xlfn.SEQUENCE(_xlpm.n), _xlfn.LAMBDA(_xlpm.acc,_xlpm.i, SUBSTITUTE( _xlpm.acc, INDEX(_xlpm.findRange, _xlpm.i), INDEX(_xlpm.replRange, _xlpm.i) ) ) ) )} -> Tooth | D21: {=_xlfn.LET( _xlpm.txt, D2, _xlpm.findRange, $X$3:$X$30, _xlpm.replRange, $Y$3:$Y$30, _xlpm.n, ROWS(_xlpm.findRange), _xlfn.REDUCE( _xlpm.txt, _xlfn.SEQUENCE(_xlpm.n), _xlfn.LAMBDA(_xlpm.acc,_xlpm.i, SUBSTITUTE( _xlpm.acc, INDEX(_xlpm.findRange, _xlpm.i), INDEX(_xlpm.replRange, _xlpm.i) ) ) ) )} -> Steel | E21: {=_xlfn.LET( _xlpm.txt, E2, _xlpm.findRange, $X$3:$X$30, _xlpm.replRange, $Y$3:$Y$30, _xlpm.n, ROWS(_xlpm.findRange), _xlfn.REDUCE( _xlpm.txt, _xlfn.SEQUENCE(_xlpm.n), _xlfn.LAMBDA(_xlpm.acc,_xlpm.i, SUBSTITUTE( _xlpm.acc, INDEX(_xlpm.findRange, _xlpm.i), INDEX(_xlpm.replRange, _xlpm.i) ) ) ) )} -> Power | F21: {=_xlfn.LET( _xlpm.txt, F2, _xlpm.findRange, $X$3:$X$30, _xlpm.replRange, $Y$3:$Y$30, _xlpm.n, ROWS(_xlpm.findRange), _xlfn.REDUCE( _xlpm.txt, _xlfn.SEQUENCE(_xlpm.n), _xlfn.LAMBDA(_xlpm.acc,_xlpm.i, SUBSTITUTE( _xlpm.acc, INDEX(_xlpm.findRange, _xlpm.i), INDEX(_xlpm.replRange, _xlpm.i) ) ) ) )} -> Spirit | G21: {=_xlfn.LET( _xlpm.txt, G2, _xlpm.findRange, $X$3:$X$30, _xlpm.replRange, $Y$3:$Y$30, _xlpm.n, ROWS(_xlpm.findRange), _xlfn.REDUCE( _xlpm.txt, _xlfn.SEQUENCE(_xlpm.n), _xlfn.LAMBDA(_xlpm.acc,_xlpm.i, SUBSTITUTE( _xlpm.acc, INDEX(_xlpm.findRange, _xlpm.i), INDEX(_xlpm.replRange, _xlpm.i) ) ) ) )} -> Feather | H21: {=_xlfn.LET( _xlpm.txt, H2, _xlpm.findRange, $X$3:$X$30, _xlpm.replRange, $Y$3:$Y$30, _xlpm.n, ROWS(_xlpm.findRange), _xlfn.REDUCE( _xlpm.txt, _xlfn.SEQUENCE(_xlpm.n), _xlfn.LAMBDA(_xlpm.acc,_xlpm.i, SUBSTITUTE( _xlpm.acc, INDEX(_xlpm.findRange, _xlpm.i), INDEX(_xlpm.replRange, _xlpm.i) ) ) ) )} -> Egg | ... Q21: {=_xlfn.LET( _xlpm.txt, Q2, _xlpm.findRange, $X$3:$X$30, _xlpm.replRange, $Y$3:$Y$30, _xlpm.n, ROWS(_xlpm.findRange), _xlfn.REDUCE( _xlpm.txt, _xlfn.SEQUENCE(_xlpm.n), _xlfn.LAMBDA(_xlpm.acc,_xlpm.i, SUBSTITUTE( _xlpm.acc, INDEX(_xlpm.findRange, _xlpm.i), INDEX(_xlpm.replRange, _xlpm.i) ) ) ) )} -> Shadow | S21: 4 Crafting Shards | U21: =IF(ISNUMBER(1*LEFT(S21, 1)), RIGHT(S21,LEN(S21)-SEARCH(" ",S21)),S21) -> Crafting Shards | V21: =ISNUMBER(MATCH(U21,$A$3:$A$18,0)) -> FALSE | X21: Event Equipment (Lab Coat) | Y21: Event Equipment | AC21: 4 Crafting Shards | AE21: =IF(ISNUMBER(1*LEFT(AC21, 1)), RIGHT(AC21,LEN(AC21)-SEARCH(" ",AC21)),AC21) -> Crafting Shards | AF21: =ISNUMBER(MATCH(AE21,$A$3:$A$18,0)) -> FALSE
A22: {=_xlfn.LET( _xlpm.txt, A3, _xlpm.findRange, $X$3:$X$30, _xlpm.replRange, $Y$3:$Y$30, _xlpm.n, ROWS(_xlpm.findRange), _xlfn.REDUCE( _xlpm.txt, _xlfn.SEQUENCE(_xlpm.n), _xlfn.LAMBDA(_xlpm.acc,_xlpm.i, SUBSTITUTE( _xlpm.acc, INDEX(_xlpm.findRange, _xlpm.i), INDEX(_xlpm.replRange, _xlpm.i) ) ) ) )} -> Poison | B22: {=_xlfn.LET( _xlpm.txt, B3, _xlpm.findRange, $X$3:$X$30, _xlpm.replRange, $Y$3:$Y$30, _xlpm.n, ROWS(_xlpm.findRange), _xlfn.REDUCE( _xlpm.txt, _xlfn.SEQUENCE(_xlpm.n), _xlfn.LAMBDA(_xlpm.acc,_xlpm.i, SUBSTITUTE( _xlpm.acc, INDEX(_xlpm.findRange, _xlpm.i), INDEX(_xlpm.replRange, _xlpm.i) ) ) ) )} -> 1 Pet Eggs | C22: {=_xlfn.LET( _xlpm.txt, C3, _xlpm.findRange, $X$3:$X$30, _xlpm.replRange, $Y$3:$Y$30, _xlpm.n, ROWS(_xlpm.findRange), _xlfn.REDUCE( _xlpm.txt, _xlfn.SEQUENCE(_xlpm.n), _xlfn.LAMBDA(_xlpm.acc,_xlpm.i, SUBSTITUTE( _xlpm.acc, INDEX(_xlpm.findRange, _xlpm.i), INDEX(_xlpm.replRange, _xlpm.i) ) ) ) )} -> Power | D22: {=_xlfn.LET( _xlpm.txt, D3, _xlpm.findRange, $X$3:$X$30, _xlpm.replRange, $Y$3:$Y$30, _xlpm.n, ROWS(_xlpm.findRange), _xlfn.REDUCE( _xlpm.txt, _xlfn.SEQUENCE(_xlpm.n), _xlfn.LAMBDA(_xlpm.acc,_xlpm.i, SUBSTITUTE( _xlpm.acc, INDEX(_xlpm.findRange, _xlpm.i), INDEX(_xlpm.replRange, _xlpm.i) ) ) ) )} -> Spirit | E22: {=_xlfn.LET( _xlpm.txt, E3, _xlpm.findRange, $X$3:$X$30, _xlpm.replRange, $Y$3:$Y$30, _xlpm.n, ROWS(_xlpm.findRange), _xlfn.REDUCE( _xlpm.txt, _xlfn.SEQUENCE(_xlpm.n), _xlfn.LAMBDA(_xlpm.acc,_xlpm.i, SUBSTITUTE( _xlpm.acc, INDEX(_xlpm.findRange, _xlpm.i), INDEX(_xlpm.replRange, _xlpm.i) ) ) ) )} -> Event Equipment | F22: {=_xlfn.LET( _xlpm.txt, F3, _xlpm.findRange, $X$3:$X$30, _xlpm.replRange, $Y$3:$Y$30, _xlpm.n, ROWS(_xlpm.findRange), _xlfn.REDUCE( _xlpm.txt, _xlfn.SEQUENCE(_xlpm.n), _xlfn.LAMBDA(_xlpm.acc,_xlpm.i, SUBSTITUTE( _xlpm.acc, INDEX(_xlpm.findRange, _xlpm.i), INDEX(_xlpm.replRange, _xlpm.i) ) ) ) )} -> 18 Currency | G22: {=_xlfn.LET( _xlpm.txt, G3, _xlpm.findRange, $X$3:$X$30, _xlpm.replRange, $Y$3:$Y$30, _xlpm.n, ROWS(_xlpm.findRange), _xlfn.REDUCE( _xlpm.txt, _xlfn.SEQUENCE(_xlpm.n), _xlfn.LAMBDA(_xlpm.acc,_xlpm.i, SUBSTITUTE( _xlpm.acc, INDEX(_xlpm.findRange, _xlpm.i), INDEX(_xlpm.replRange, _xlpm.i) ) ) ) )} -> Egg | H22: {=_xlfn.LET( _xlpm.txt, H3, _xlpm.findRange, $X$3:$X$30, _xlpm.replRange, $Y$3:$Y$30, _xlpm.n, ROWS(_xlpm.findRange), _xlfn.REDUCE( _xlpm.txt, _xlfn.SEQUENCE(_xlpm.n), _xlfn.LAMBDA(_xlpm.acc,_xlpm.i, SUBSTITUTE( _xlpm.acc, INDEX(_xlpm.findRange, _xlpm.i), INDEX(_xlpm.replRange, _xlpm.i) ) ) ) )} -> 1 Skill Points | ... Q22: {=_xlfn.LET( _xlpm.txt, Q3, _xlpm.findRange, $X$3:$X$30, _xlpm.replRange, $Y$3:$Y$30, _xlpm.n, ROWS(_xlpm.findRange), _xlfn.REDUCE( _xlpm.txt, _xlfn.SEQUENCE(_xlpm.n), _xlfn.LAMBDA(_xlpm.acc,_xlpm.i, SUBSTITUTE( _xlpm.acc, INDEX(_xlpm.findRange, _xlpm.i), INDEX(_xlpm.replRange, _xlpm.i) ) ) ) )} -> 222 Currency | S22: 2 Perks | U22: =IF(ISNUMBER(1*LEFT(S22, 1)), RIGHT(S22,LEN(S22)-SEARCH(" ",S22)),S22) -> Perks | V22: =ISNUMBER(MATCH(U22,$A$3:$A$18,0)) -> FALSE | X22: Event Equipment | Y22: Event Equipment | AC22: 2 Perks | AE22: =IF(ISNUMBER(1*LEFT(AC22, 1)), RIGHT(AC22,LEN(AC22)-SEARCH(" ",AC22)),AC22) -> Perks | AF22: =ISNUMBER(MATCH(AE22,$A$3:$A$18,0)) -> FALSE
A23: {=_xlfn.LET( _xlpm.txt, A4, _xlpm.findRange, $X$3:$X$30, _xlpm.replRange, $Y$3:$Y$30, _xlpm.n, ROWS(_xlpm.findRange), _xlfn.REDUCE( _xlpm.txt, _xlfn.SEQUENCE(_xlpm.n), _xlfn.LAMBDA(_xlpm.acc,_xlpm.i, SUBSTITUTE( _xlpm.acc, INDEX(_xlpm.findRange, _xlpm.i), INDEX(_xlpm.replRange, _xlpm.i) ) ) ) )} -> Tooth | B23: {=_xlfn.LET( _xlpm.txt, B4, _xlpm.findRange, $X$3:$X$30, _xlpm.replRange, $Y$3:$Y$30, _xlpm.n, ROWS(_xlpm.findRange), _xlfn.REDUCE( _xlpm.txt, _xlfn.SEQUENCE(_xlpm.n), _xlfn.LAMBDA(_xlpm.acc,_xlpm.i, SUBSTITUTE( _xlpm.acc, INDEX(_xlpm.findRange, _xlpm.i), INDEX(_xlpm.replRange, _xlpm.i) ) ) ) )} -> Power | C23: {=_xlfn.LET( _xlpm.txt, C4, _xlpm.findRange, $X$3:$X$30, _xlpm.replRange, $Y$3:$Y$30, _xlpm.n, ROWS(_xlpm.findRange), _xlfn.REDUCE( _xlpm.txt, _xlfn.SEQUENCE(_xlpm.n), _xlfn.LAMBDA(_xlpm.acc,_xlpm.i, SUBSTITUTE( _xlpm.acc, INDEX(_xlpm.findRange, _xlpm.i), INDEX(_xlpm.replRange, _xlpm.i) ) ) ) )} -> 12 Currency | D23: {=_xlfn.LET( _xlpm.txt, D4, _xlpm.findRange, $X$3:$X$30, _xlpm.replRange, $Y$3:$Y$30, _xlpm.n, ROWS(_xlpm.findRange), _xlfn.REDUCE( _xlpm.txt, _xlfn.SEQUENCE(_xlpm.n), _xlfn.LAMBDA(_xlpm.acc,_xlpm.i, SUBSTITUTE( _xlpm.acc, INDEX(_xlpm.findRange, _xlpm.i), INDEX(_xlpm.replRange, _xlpm.i) ) ) ) )} -> Feather | E23: {=_xlfn.LET( _xlpm.txt, E4, _xlpm.findRange, $X$3:$X$30, _xlpm.replRange, $Y$3:$Y$30, _xlpm.n, ROWS(_xlpm.findRange), _xlfn.REDUCE( _xlpm.txt, _xlfn.SEQUENCE(_xlpm.n), _xlfn.LAMBDA(_xlpm.acc,_xlpm.i, SUBSTITUTE( _xlpm.acc, INDEX(_xlpm.findRange, _xlpm.i), INDEX(_xlpm.replRange, _xlpm.i) ) ) ) )} -> 18 Currency | F23: {=_xlfn.LET( _xlpm.txt, F4, _xlpm.findRange, $X$3:$X$30, _xlpm.replRange, $Y$3:$Y$30, _xlpm.n, ROWS(_xlpm.findRange), _xlfn.REDUCE( _xlpm.txt, _xlfn.SEQUENCE(_xlpm.n), _xlfn.LAMBDA(_xlpm.acc,_xlpm.i, SUBSTITUTE( _xlpm.acc, INDEX(_xlpm.findRange, _xlpm.i), INDEX(_xlpm.replRange, _xlpm.i) ) ) ) )} -> 1 Perks | G23: {=_xlfn.LET( _xlpm.txt, G4, _xlpm.findRange, $X$3:$X$30, _xlpm.replRange, $Y$3:$Y$30, _xlpm.n, ROWS(_xlpm.findRange), _xlfn.REDUCE( _xlpm.txt, _xlfn.SEQUENCE(_xlpm.n), _xlfn.LAMBDA(_xlpm.acc,_xlpm.i, SUBSTITUTE( _xlpm.acc, INDEX(_xlpm.findRange, _xlpm.i), INDEX(_xlpm.replRange, _xlpm.i) ) ) ) )} -> Event Equipment | H23: {=_xlfn.LET( _xlpm.txt, H4, _xlpm.findRange, $X$3:$X$30, _xlpm.replRange, $Y$3:$Y$30, _xlpm.n, ROWS(_xlpm.findRange), _xlfn.REDUCE( _xlpm.txt, _xlfn.SEQUENCE(_xlpm.n), _xlfn.LAMBDA(_xlpm.acc,_xlpm.i, SUBSTITUTE( _xlpm.acc, INDEX(_xlpm.findRange, _xlpm.i), INDEX(_xlpm.replRange, _xlpm.i) ) ) ) )} -> 1 Raid Cards | ... Q23: {=_xlfn.LET( _xlpm.txt, Q4, _xlpm.findRange, $X$3:$X$30, _xlpm.replRange, $Y$3:$Y$30, _xlpm.n, ROWS(_xlpm.findRange), _xlfn.REDUCE( _xlpm.txt, _xlfn.SEQUENCE(_xlpm.n), _xlfn.LAMBDA(_xlpm.acc,_xlpm.i, SUBSTITUTE( _xlpm.acc, INDEX(_xlpm.findRange, _xlpm.i), INDEX(_xlpm.replRange, _xlpm.i) ) ) ) )} -> 3 Clan Scrolls | S23: 60 Currency | U23: =IF(ISNUMBER(1*LEFT(S23, 1)), RIGHT(S23,LEN(S23)-SEARCH(" ",S23)),S23) -> Currency | V23: =ISNUMBER(MATCH(U23,$A$3:$A$18,0)) -> FALSE | X23: Event Equipment | Y23: Event Equipment | AC23: 6 Currency | AE23: =IF(ISNUMBER(1*LEFT(AC23, 1)), RIGHT(AC23,LEN(AC23)-SEARCH(" ",AC23)),AC23) -> Currency | AF23: =ISNUMBER(MATCH(AE23,$A$3:$A$18,0)) -> FALSE
A24: {=_xlfn.LET( _xlpm.txt, A5, _xlpm.findRange, $X$3:$X$30, _xlpm.replRange, $Y$3:$Y$30, _xlpm.n, ROWS(_xlpm.findRange), _xlfn.REDUCE( _xlpm.txt, _xlfn.SEQUENCE(_xlpm.n), _xlfn.LAMBDA(_xlpm.acc,_xlpm.i, SUBSTITUTE( _xlpm.acc, INDEX(_xlpm.findRange, _xlpm.i), INDEX(_xlpm.replRange, _xlpm.i) ) ) ) )} -> Steel | B24: {=_xlfn.LET( _xlpm.txt, B5, _xlpm.findRange, $X$3:$X$30, _xlpm.replRange, $Y$3:$Y$30, _xlpm.n, ROWS(_xlpm.findRange), _xlfn.REDUCE( _xlpm.txt, _xlfn.SEQUENCE(_xlpm.n), _xlfn.LAMBDA(_xlpm.acc,_xlpm.i, SUBSTITUTE( _xlpm.acc, INDEX(_xlpm.findRange, _xlpm.i), INDEX(_xlpm.replRange, _xlpm.i) ) ) ) )} -> Spirit | C24: {=_xlfn.LET( _xlpm.txt, C5, _xlpm.findRange, $X$3:$X$30, _xlpm.replRange, $Y$3:$Y$30, _xlpm.n, ROWS(_xlpm.findRange), _xlfn.REDUCE( _xlpm.txt, _xlfn.SEQUENCE(_xlpm.n), _xlfn.LAMBDA(_xlpm.acc,_xlpm.i, SUBSTITUTE( _xlpm.acc, INDEX(_xlpm.findRange, _xlpm.i), INDEX(_xlpm.replRange, _xlpm.i) ) ) ) )} -> Feather | D24: {=_xlfn.LET( _xlpm.txt, D5, _xlpm.findRange, $X$3:$X$30, _xlpm.replRange, $Y$3:$Y$30, _xlpm.n, ROWS(_xlpm.findRange), _xlfn.REDUCE( _xlpm.txt, _xlfn.SEQUENCE(_xlpm.n), _xlfn.LAMBDA(_xlpm.acc,_xlpm.i, SUBSTITUTE( _xlpm.acc, INDEX(_xlpm.findRange, _xlpm.i), INDEX(_xlpm.replRange, _xlpm.i) ) ) ) )} -> 12 Currency | E24: {=_xlfn.LET( _xlpm.txt, E5, _xlpm.findRange, $X$3:$X$30, _xlpm.replRange, $Y$3:$Y$30, _xlpm.n, ROWS(_xlpm.findRange), _xlfn.REDUCE( _xlpm.txt, _xlfn.SEQUENCE(_xlpm.n), _xlfn.LAMBDA(_xlpm.acc,_xlpm.i, SUBSTITUTE( _xlpm.acc, INDEX(_xlpm.findRange, _xlpm.i), INDEX(_xlpm.replRange, _xlpm.i) ) ) ) )} -> 6 Raid Cards | F24: {=_xlfn.LET( _xlpm.txt, F5, _xlpm.findRange, $X$3:$X$30, _xlpm.replRange, $Y$3:$Y$30, _xlpm.n, ROWS(_xlpm.findRange), _xlfn.REDUCE( _xlpm.txt, _xlfn.SEQUENCE(_xlpm.n), _xlfn.LAMBDA(_xlpm.acc,_xlpm.i, SUBSTITUTE( _xlpm.acc, INDEX(_xlpm.findRange, _xlpm.i), INDEX(_xlpm.replRange, _xlpm.i) ) ) ) )} -> 1 Event Equipment | G24: {=_xlfn.LET( _xlpm.txt, G5, _xlpm.findRange, $X$3:$X$30, _xlpm.replRange, $Y$3:$Y$30, _xlpm.n, ROWS(_xlpm.findRange), _xlfn.REDUCE( _xlpm.txt, _xlfn.SEQUENCE(_xlpm.n), _xlfn.LAMBDA(_xlpm.acc,_xlpm.i, SUBSTITUTE( _xlpm.acc, INDEX(_xlpm.findRange, _xlpm.i), INDEX(_xlpm.replRange, _xlpm.i) ) ) ) )} -> 3 Pet Eggs | H24: {=_xlfn.LET( _xlpm.txt, H5, _xlpm.findRange, $X$3:$X$30, _xlpm.replRange, $Y$3:$Y$30, _xlpm.n, ROWS(_xlpm.findRange), _xlfn.REDUCE( _xlpm.txt, _xlfn.SEQUENCE(_xlpm.n), _xlfn.LAMBDA(_xlpm.acc,_xlpm.i, SUBSTITUTE( _xlpm.acc, INDEX(_xlpm.findRange, _xlpm.i), INDEX(_xlpm.replRange, _xlpm.i) ) ) ) )} -> 1 Raid Cards | ... Q24: {=_xlfn.LET( _xlpm.txt, Q5, _xlpm.findRange, $X$3:$X$30, _xlpm.replRange, $Y$3:$Y$30, _xlpm.n, ROWS(_xlpm.findRange), _xlfn.REDUCE( _xlpm.txt, _xlfn.SEQUENCE(_xlpm.n), _xlfn.LAMBDA(_xlpm.acc,_xlpm.i, SUBSTITUTE( _xlpm.acc, INDEX(_xlpm.findRange, _xlpm.i), INDEX(_xlpm.replRange, _xlpm.i) ) ) ) )} -> 232 Currency | S24: 3 Perks | U24: =IF(ISNUMBER(1*LEFT(S24, 1)), RIGHT(S24,LEN(S24)-SEARCH(" ",S24)),S24) -> Perks | V24: =ISNUMBER(MATCH(U24,$A$3:$A$18,0)) -> FALSE | X24: Currency | Y24: Currency | AC24: 3 Perks | AE24: =IF(ISNUMBER(1*LEFT(AC24, 1)), RIGHT(AC24,LEN(AC24)-SEARCH(" ",AC24)),AC24) -> Perks | AF24: =ISNUMBER(MATCH(AE24,$A$3:$A$18,0)) -> FALSE
A25: {=_xlfn.LET( _xlpm.txt, A6, _xlpm.findRange, $X$3:$X$30, _xlpm.replRange, $Y$3:$Y$30, _xlpm.n, ROWS(_xlpm.findRange), _xlfn.REDUCE( _xlpm.txt, _xlfn.SEQUENCE(_xlpm.n), _xlfn.LAMBDA(_xlpm.acc,_xlpm.i, SUBSTITUTE( _xlpm.acc, INDEX(_xlpm.findRange, _xlpm.i), INDEX(_xlpm.replRange, _xlpm.i) ) ) ) )} -> Power | B25: {=_xlfn.LET( _xlpm.txt, B6, _xlpm.findRange, $X$3:$X$30, _xlpm.replRange, $Y$3:$Y$30, _xlpm.n, ROWS(_xlpm.findRange), _xlfn.REDUCE( _xlpm.txt, _xlfn.SEQUENCE(_xlpm.n), _xlfn.LAMBDA(_xlpm.acc,_xlpm.i, SUBSTITUTE( _xlpm.acc, INDEX(_xlpm.findRange, _xlpm.i), INDEX(_xlpm.replRange, _xlpm.i) ) ) ) )} -> Event Equipment | C25: {=_xlfn.LET( _xlpm.txt, C6, _xlpm.findRange, $X$3:$X$30, _xlpm.replRange, $Y$3:$Y$30, _xlpm.n, ROWS(_xlpm.findRange), _xlfn.REDUCE( _xlpm.txt, _xlfn.SEQUENCE(_xlpm.n), _xlfn.LAMBDA(_xlpm.acc,_xlpm.i, SUBSTITUTE( _xlpm.acc, INDEX(_xlpm.findRange, _xlpm.i), INDEX(_xlpm.replRange, _xlpm.i) ) ) ) )} -> 18 Currency | D25: {=_xlfn.LET( _xlpm.txt, D6, _xlpm.findRange, $X$3:$X$30, _xlpm.replRange, $Y$3:$Y$30, _xlpm.n, ROWS(_xlpm.findRange), _xlfn.REDUCE( _xlpm.txt, _xlfn.SEQUENCE(_xlpm.n), _xlfn.LAMBDA(_xlpm.acc,_xlpm.i, SUBSTITUTE( _xlpm.acc, INDEX(_xlpm.findRange, _xlpm.i), INDEX(_xlpm.replRange, _xlpm.i) ) ) ) )} -> 6 Raid Cards | E25: {=_xlfn.LET( _xlpm.txt, E6, _xlpm.findRange, $X$3:$X$30, _xlpm.replRange, $Y$3:$Y$30, _xlpm.n, ROWS(_xlpm.findRange), _xlfn.REDUCE( _xlpm.txt, _xlfn.SEQUENCE(_xlpm.n), _xlfn.LAMBDA(_xlpm.acc,_xlpm.i, SUBSTITUTE( _xlpm.acc, INDEX(_xlpm.findRange, _xlpm.i), INDEX(_xlpm.replRange, _xlpm.i) ) ) ) )} -> 2 Event Equipment | F25: {=_xlfn.LET( _xlpm.txt, F6, _xlpm.findRange, $X$3:$X$30, _xlpm.replRange, $Y$3:$Y$30, _xlpm.n, ROWS(_xlpm.findRange), _xlfn.REDUCE( _xlpm.txt, _xlfn.SEQUENCE(_xlpm.n), _xlfn.LAMBDA(_xlpm.acc,_xlpm.i, SUBSTITUTE( _xlpm.acc, INDEX(_xlpm.findRange, _xlpm.i), INDEX(_xlpm.replRange, _xlpm.i) ) ) ) )} -> 25 Currency | G25: {=_xlfn.LET( _xlpm.txt, G6, _xlpm.findRange, $X$3:$X$30, _xlpm.replRange, $Y$3:$Y$30, _xlpm.n, ROWS(_xlpm.findRange), _xlfn.REDUCE( _xlpm.txt, _xlfn.SEQUENCE(_xlpm.n), _xlfn.LAMBDA(_xlpm.acc,_xlpm.i, SUBSTITUTE( _xlpm.acc, INDEX(_xlpm.findRange, _xlpm.i), INDEX(_xlpm.replRange, _xlpm.i) ) ) ) )} -> Pepper | H25: {=_xlfn.LET( _xlpm.txt, H6, _xlpm.findRange, $X$3:$X$30, _xlpm.replRange, $Y$3:$Y$30, _xlpm.n, ROWS(_xlpm.findRange), _xlfn.REDUCE( _xlpm.txt, _xlfn.SEQUENCE(_xlpm.n), _xlfn.LAMBDA(_xlpm.acc,_xlpm.i, SUBSTITUTE( _xlpm.acc, INDEX(_xlpm.findRange, _xlpm.i), INDEX(_xlpm.replRange, _xlpm.i) ) ) ) )} -> 2 Hero Weapons | ... Q25: {=_xlfn.LET( _xlpm.txt, Q6, _xlpm.findRange, $X$3:$X$30, _xlpm.replRange, $Y$3:$Y$30, _xlpm.n, ROWS(_xlpm.findRange), _xlfn.REDUCE( _xlpm.txt, _xlfn.SEQUENCE(_xlpm.n), _xlfn.LAMBDA(_xlpm.acc,_xlpm.i, SUBSTITUTE( _xlpm.acc, INDEX(_xlpm.findRange, _xlpm.i), INDEX(_xlpm.replRange, _xlpm.i) ) ) ) )} -> 3 Clan Scrolls | S25: 3 Clan Scrolls | U25: =IF(ISNUMBER(1*LEFT(S25, 1)), RIGHT(S25,LEN(S25)-SEARCH(" ",S25)),S25) -> Clan Scrolls | V25: =ISNUMBER(MATCH(U25,$A$3:$A$18,0)) -> FALSE | X25: Crafting Shards | Y25: Crafting Shards | AC25: 3 Clan Scrolls | AE25: =IF(ISNUMBER(1*LEFT(AC25, 1)), RIGHT(AC25,LEN(AC25)-SEARCH(" ",AC25)),AC25) -> Clan Scrolls | AF25: =ISNUMBER(MATCH(AE25,$A$3:$A$18,0)) -> FALSE
A26: {=_xlfn.LET( _xlpm.txt, A7, _xlpm.findRange, $X$3:$X$30, _xlpm.replRange, $Y$3:$Y$30, _xlpm.n, ROWS(_xlpm.findRange), _xlfn.REDUCE( _xlpm.txt, _xlfn.SEQUENCE(_xlpm.n), _xlfn.LAMBDA(_xlpm.acc,_xlpm.i, SUBSTITUTE( _xlpm.acc, INDEX(_xlpm.findRange, _xlpm.i), INDEX(_xlpm.replRange, _xlpm.i) ) ) ) )} -> Spirit | B26: {=_xlfn.LET( _xlpm.txt, B7, _xlpm.findRange, $X$3:$X$30, _xlpm.replRange, $Y$3:$Y$30, _xlpm.n, ROWS(_xlpm.findRange), _xlfn.REDUCE( _xlpm.txt, _xlfn.SEQUENCE(_xlpm.n), _xlfn.LAMBDA(_xlpm.acc,_xlpm.i, SUBSTITUTE( _xlpm.acc, INDEX(_xlpm.findRange, _xlpm.i), INDEX(_xlpm.replRange, _xlpm.i) ) ) ) )} -> 18 Currency | C26: {=_xlfn.LET( _xlpm.txt, C7, _xlpm.findRange, $X$3:$X$30, _xlpm.replRange, $Y$3:$Y$30, _xlpm.n, ROWS(_xlpm.findRange), _xlfn.REDUCE( _xlpm.txt, _xlfn.SEQUENCE(_xlpm.n), _xlfn.LAMBDA(_xlpm.acc,_xlpm.i, SUBSTITUTE( _xlpm.acc, INDEX(_xlpm.findRange, _xlpm.i), INDEX(_xlpm.replRange, _xlpm.i) ) ) ) )} -> 1 Perks | D26: {=_xlfn.LET( _xlpm.txt, D7, _xlpm.findRange, $X$3:$X$30, _xlpm.replRange, $Y$3:$Y$30, _xlpm.n, ROWS(_xlpm.findRange), _xlfn.REDUCE( _xlpm.txt, _xlfn.SEQUENCE(_xlpm.n), _xlfn.LAMBDA(_xlpm.acc,_xlpm.i, SUBSTITUTE( _xlpm.acc, INDEX(_xlpm.findRange, _xlpm.i), INDEX(_xlpm.replRange, _xlpm.i) ) ) ) )} -> 1 Event Equipment | E26: {=_xlfn.LET( _xlpm.txt, E7, _xlpm.findRange, $X$3:$X$30, _xlpm.replRange, $Y$3:$Y$30, _xlpm.n, ROWS(_xlpm.findRange), _xlfn.REDUCE( _xlpm.txt, _xlfn.SEQUENCE(_xlpm.n), _xlfn.LAMBDA(_xlpm.acc,_xlpm.i, SUBSTITUTE( _xlpm.acc, INDEX(_xlpm.findRange, _xlpm.i), INDEX(_xlpm.replRange, _xlpm.i) ) ) ) )} -> 25 Currency | F26: {=_xlfn.LET( _xlpm.txt, F7, _xlpm.findRange, $X$3:$X$30, _xlpm.replRange, $Y$3:$Y$30, _xlpm.n, ROWS(_xlpm.findRange), _xlfn.REDUCE( _xlpm.txt, _xlfn.SEQUENCE(_xlpm.n), _xlfn.LAMBDA(_xlpm.acc,_xlpm.i, SUBSTITUTE( _xlpm.acc, INDEX(_xlpm.findRange, _xlpm.i), INDEX(_xlpm.replRange, _xlpm.i) ) ) ) )} -> 25 Currency | G26: {=_xlfn.LET( _xlpm.txt, G7, _xlpm.findRange, $X$3:$X$30, _xlpm.replRange, $Y$3:$Y$30, _xlpm.n, ROWS(_xlpm.findRange), _xlfn.REDUCE( _xlpm.txt, _xlfn.SEQUENCE(_xlpm.n), _xlfn.LAMBDA(_xlpm.acc,_xlpm.i, SUBSTITUTE( _xlpm.acc, INDEX(_xlpm.findRange, _xlpm.i), INDEX(_xlpm.replRange, _xlpm.i) ) ) ) )} -> Mushroom | H26: {=_xlfn.LET( _xlpm.txt, H7, _xlpm.findRange, $X$3:$X$30, _xlpm.replRange, $Y$3:$Y$30, _xlpm.n, ROWS(_xlpm.findRange), _xlfn.REDUCE( _xlpm.txt, _xlfn.SEQUENCE(_xlpm.n), _xlfn.LAMBDA(_xlpm.acc,_xlpm.i, SUBSTITUTE( _xlpm.acc, INDEX(_xlpm.findRange, _xlpm.i), INDEX(_xlpm.replRange, _xlpm.i) ) ) ) )} -> 38 Currency | ... Q26: {=_xlfn.LET( _xlpm.txt, Q7, _xlpm.findRange, $X$3:$X$30, _xlpm.replRange, $Y$3:$Y$30, _xlpm.n, ROWS(_xlpm.findRange), _xlfn.REDUCE( _xlpm.txt, _xlfn.SEQUENCE(_xlpm.n), _xlfn.LAMBDA(_xlpm.acc,_xlpm.i, SUBSTITUTE( _xlpm.acc, INDEX(_xlpm.findRange, _xlpm.i), INDEX(_xlpm.replRange, _xlpm.i) ) ) ) )} -> 238 Currency | S26: 6 Raid Cards | U26: =IF(ISNUMBER(1*LEFT(S26, 1)), RIGHT(S26,LEN(S26)-SEARCH(" ",S26)),S26) -> Raid Cards | V26: =ISNUMBER(MATCH(U26,$A$3:$A$18,0)) -> FALSE | X26: Clan Scrolls | Y26: Clan Scroll | AC26: 6 Raid Cards | AE26: =IF(ISNUMBER(1*LEFT(AC26, 1)), RIGHT(AC26,LEN(AC26)-SEARCH(" ",AC26)),AC26) -> Raid Cards | AF26: =ISNUMBER(MATCH(AE26,$A$3:$A$18,0)) -> FALSE
A27: {=_xlfn.LET( _xlpm.txt, A8, _xlpm.findRange, $X$3:$X$30, _xlpm.replRange, $Y$3:$Y$30, _xlpm.n, ROWS(_xlpm.findRange), _xlfn.REDUCE( _xlpm.txt, _xlfn.SEQUENCE(_xlpm.n), _xlfn.LAMBDA(_xlpm.acc,_xlpm.i, SUBSTITUTE( _xlpm.acc, INDEX(_xlpm.findRange, _xlpm.i), INDEX(_xlpm.replRange, _xlpm.i) ) ) ) )} -> Feather | B27: {=_xlfn.LET( _xlpm.txt, B8, _xlpm.findRange, $X$3:$X$30, _xlpm.replRange, $Y$3:$Y$30, _xlpm.n, ROWS(_xlpm.findRange), _xlfn.REDUCE( _xlpm.txt, _xlfn.SEQUENCE(_xlpm.n), _xlfn.LAMBDA(_xlpm.acc,_xlpm.i, SUBSTITUTE( _xlpm.acc, INDEX(_xlpm.findRange, _xlpm.i), INDEX(_xlpm.replRange, _xlpm.i) ) ) ) )} -> Egg | C27: {=_xlfn.LET( _xlpm.txt, C8, _xlpm.findRange, $X$3:$X$30, _xlpm.replRange, $Y$3:$Y$30, _xlpm.n, ROWS(_xlpm.findRange), _xlfn.REDUCE( _xlpm.txt, _xlfn.SEQUENCE(_xlpm.n), _xlfn.LAMBDA(_xlpm.acc,_xlpm.i, SUBSTITUTE( _xlpm.acc, INDEX(_xlpm.findRange, _xlpm.i), INDEX(_xlpm.replRange, _xlpm.i) ) ) ) )} -> Event Equipment | D27: {=_xlfn.LET( _xlpm.txt, D8, _xlpm.findRange, $X$3:$X$30, _xlpm.replRange, $Y$3:$Y$30, _xlpm.n, ROWS(_xlpm.findRange), _xlfn.REDUCE( _xlpm.txt, _xlfn.SEQUENCE(_xlpm.n), _xlfn.LAMBDA(_xlpm.acc,_xlpm.i, SUBSTITUTE( _xlpm.acc, INDEX(_xlpm.findRange, _xlpm.i), INDEX(_xlpm.replRange, _xlpm.i) ) ) ) )} -> 3 Pet Eggs | E27: {=_xlfn.LET( _xlpm.txt, E8, _xlpm.findRange, $X$3:$X$30, _xlpm.replRange, $Y$3:$Y$30, _xlpm.n, ROWS(_xlpm.findRange), _xlfn.REDUCE( _xlpm.txt, _xlfn.SEQUENCE(_xlpm.n), _xlfn.LAMBDA(_xlpm.acc,_xlpm.i, SUBSTITUTE( _xlpm.acc, INDEX(_xlpm.findRange, _xlpm.i), INDEX(_xlpm.replRange, _xlpm.i) ) ) ) )} -> Pepper | F27: {=_xlfn.LET( _xlpm.txt, F8, _xlpm.findRange, $X$3:$X$30, _xlpm.replRange, $Y$3:$Y$30, _xlpm.n, ROWS(_xlpm.findRange), _xlfn.REDUCE( _xlpm.txt, _xlfn.SEQUENCE(_xlpm.n), _xlfn.LAMBDA(_xlpm.acc,_xlpm.i, SUBSTITUTE( _xlpm.acc, INDEX(_xlpm.findRange, _xlpm.i), INDEX(_xlpm.replRange, _xlpm.i) ) ) ) )} -> Mushroom | G27: {=_xlfn.LET( _xlpm.txt, G8, _xlpm.findRange, $X$3:$X$30, _xlpm.replRange, $Y$3:$Y$30, _xlpm.n, ROWS(_xlpm.findRange), _xlfn.REDUCE( _xlpm.txt, _xlfn.SEQUENCE(_xlpm.n), _xlfn.LAMBDA(_xlpm.acc,_xlpm.i, SUBSTITUTE( _xlpm.acc, INDEX(_xlpm.findRange, _xlpm.i), INDEX(_xlpm.replRange, _xlpm.i) ) ) ) )} -> 25 Currency | H27: {=_xlfn.LET( _xlpm.txt, H8, _xlpm.findRange, $X$3:$X$30, _xlpm.replRange, $Y$3:$Y$30, _xlpm.n, ROWS(_xlpm.findRange), _xlfn.REDUCE( _xlpm.txt, _xlfn.SEQUENCE(_xlpm.n), _xlfn.LAMBDA(_xlpm.acc,_xlpm.i, SUBSTITUTE( _xlpm.acc, INDEX(_xlpm.findRange, _xlpm.i), INDEX(_xlpm.replRange, _xlpm.i) ) ) ) )} -> 6 Pet Eggs | ... Q27: {=_xlfn.LET( _xlpm.txt, Q8, _xlpm.findRange, $X$3:$X$30, _xlpm.replRange, $Y$3:$Y$30, _xlpm.n, ROWS(_xlpm.findRange), _xlfn.REDUCE( _xlpm.txt, _xlfn.SEQUENCE(_xlpm.n), _xlfn.LAMBDA(_xlpm.acc,_xlpm.i, SUBSTITUTE( _xlpm.acc, INDEX(_xlpm.findRange, _xlpm.i), INDEX(_xlpm.replRange, _xlpm.i) ) ) ) )} -> 39 Pet Eggs | S27: 1 Rare Equipment | U27: =IF(ISNUMBER(1*LEFT(S27, 1)), RIGHT(S27,LEN(S27)-SEARCH(" ",S27)),S27) -> Rare Equipment | V27: =ISNUMBER(MATCH(U27,$A$3:$A$18,0)) -> FALSE | X27: Clan Scroll | Y27: Clan Scrolls | AC27: 1 Event Equipment | AE27: =IF(ISNUMBER(1*LEFT(AC27, 1)), RIGHT(AC27,LEN(AC27)-SEARCH(" ",AC27)),AC27) -> Event Equipment | AF27: =ISNUMBER(MATCH(AE27,$A$3:$A$18,0)) -> FALSE
A28: {=_xlfn.LET( _xlpm.txt, A9, _xlpm.findRange, $X$3:$X$30, _xlpm.replRange, $Y$3:$Y$30, _xlpm.n, ROWS(_xlpm.findRange), _xlfn.REDUCE( _xlpm.txt, _xlfn.SEQUENCE(_xlpm.n), _xlfn.LAMBDA(_xlpm.acc,_xlpm.i, SUBSTITUTE( _xlpm.acc, INDEX(_xlpm.findRange, _xlpm.i), INDEX(_xlpm.replRange, _xlpm.i) ) ) ) )} -> Egg | B28: {=_xlfn.LET( _xlpm.txt, B9, _xlpm.findRange, $X$3:$X$30, _xlpm.replRange, $Y$3:$Y$30, _xlpm.n, ROWS(_xlpm.findRange), _xlfn.REDUCE( _xlpm.txt, _xlfn.SEQUENCE(_xlpm.n), _xlfn.LAMBDA(_xlpm.acc,_xlpm.i, SUBSTITUTE( _xlpm.acc, INDEX(_xlpm.findRange, _xlpm.i), INDEX(_xlpm.replRange, _xlpm.i) ) ) ) )} -> 1 Skill Points | C28: {=_xlfn.LET( _xlpm.txt, C9, _xlpm.findRange, $X$3:$X$30, _xlpm.replRange, $Y$3:$Y$30, _xlpm.n, ROWS(_xlpm.findRange), _xlfn.REDUCE( _xlpm.txt, _xlfn.SEQUENCE(_xlpm.n), _xlfn.LAMBDA(_xlpm.acc,_xlpm.i, SUBSTITUTE( _xlpm.acc, INDEX(_xlpm.findRange, _xlpm.i), INDEX(_xlpm.replRange, _xlpm.i) ) ) ) )} -> 1 Raid Cards | D28: {=_xlfn.LET( _xlpm.txt, D9, _xlpm.findRange, $X$3:$X$30, _xlpm.replRange, $Y$3:$Y$30, _xlpm.n, ROWS(_xlpm.findRange), _xlfn.REDUCE( _xlpm.txt, _xlfn.SEQUENCE(_xlpm.n), _xlfn.LAMBDA(_xlpm.acc,_xlpm.i, SUBSTITUTE( _xlpm.acc, INDEX(_xlpm.findRange, _xlpm.i), INDEX(_xlpm.replRange, _xlpm.i) ) ) ) )} -> 1 Raid Cards | E28: {=_xlfn.LET( _xlpm.txt, E9, _xlpm.findRange, $X$3:$X$30, _xlpm.replRange, $Y$3:$Y$30, _xlpm.n, ROWS(_xlpm.findRange), _xlfn.REDUCE( _xlpm.txt, _xlfn.SEQUENCE(_xlpm.n), _xlfn.LAMBDA(_xlpm.acc,_xlpm.i, SUBSTITUTE( _xlpm.acc, INDEX(_xlpm.findRange, _xlpm.i), INDEX(_xlpm.replRange, _xlpm.i) ) ) ) )} -> 2 Hero Weapons | F28: {=_xlfn.LET( _xlpm.txt, F9, _xlpm.findRange, $X$3:$X$30, _xlpm.replRange, $Y$3:$Y$30, _xlpm.n, ROWS(_xlpm.findRange), _xlfn.REDUCE( _xlpm.txt, _xlfn.SEQUENCE(_xlpm.n), _xlfn.LAMBDA(_xlpm.acc,_xlpm.i, SUBSTITUTE( _xlpm.acc, INDEX(_xlpm.findRange, _xlpm.i), INDEX(_xlpm.replRange, _xlpm.i) ) ) ) )} -> 38 Currency | G28: {=_xlfn.LET( _xlpm.txt, G9, _xlpm.findRange, $X$3:$X$30, _xlpm.replRange, $Y$3:$Y$30, _xlpm.n, ROWS(_xlpm.findRange), _xlfn.REDUCE( _xlpm.txt, _xlfn.SEQUENCE(_xlpm.n), _xlfn.LAMBDA(_xlpm.acc,_xlpm.i, SUBSTITUTE( _xlpm.acc, INDEX(_xlpm.findRange, _xlpm.i), INDEX(_xlpm.replRange, _xlpm.i) ) ) ) )} -> 6 Pet Eggs | H28: {=_xlfn.LET( _xlpm.txt, H9, _xlpm.findRange, $X$3:$X$30, _xlpm.replRange, $Y$3:$Y$30, _xlpm.n, ROWS(_xlpm.findRange), _xlfn.REDUCE( _xlpm.txt, _xlfn.SEQUENCE(_xlpm.n), _xlfn.LAMBDA(_xlpm.acc,_xlpm.i, SUBSTITUTE( _xlpm.acc, INDEX(_xlpm.findRange, _xlpm.i), INDEX(_xlpm.replRange, _xlpm.i) ) ) ) )} -> 52 Currency | ... Q28: {=_xlfn.LET( _xlpm.txt, Q9, _xlpm.findRange, $X$3:$X$30, _xlpm.replRange, $Y$3:$Y$30, _xlpm.n, ROWS(_xlpm.findRange), _xlfn.REDUCE( _xlpm.txt, _xlfn.SEQUENCE(_xlpm.n), _xlfn.LAMBDA(_xlpm.acc,_xlpm.i, SUBSTITUTE( _xlpm.acc, INDEX(_xlpm.findRange, _xlpm.i), INDEX(_xlpm.replRange, _xlpm.i) ) ) ) )} -> 252 Currency | S28: 3 Pet Eggs | U28: =IF(ISNUMBER(1*LEFT(S28, 1)), RIGHT(S28,LEN(S28)-SEARCH(" ",S28)),S28) -> Pet Eggs | V28: =ISNUMBER(MATCH(U28,$A$3:$A$18,0)) -> FALSE | X28: 0 | AC28: 3 Pet Eggs | AE28: =IF(ISNUMBER(1*LEFT(AC28, 1)), RIGHT(AC28,LEN(AC28)-SEARCH(" ",AC28)),AC28) -> Pet Eggs | AF28: =ISNUMBER(MATCH(AE28,$A$3:$A$18,0)) -> FALSE
